Workbook

Sheet Acerno_Cache_XXXXX

Sheet Net pay recomputation
B1: 1. EMP 3866 | F1: 2. EMP 0004 | J1: 3. EMP 0040 | N1: 4. EMP 0089 | R1: 5. EMP 0158 | V1: EMP 0204 | Z1: EMP 0303 | AD1: EMP 0495 | AH1: EMP 0500 | AL1: EMP 0525 | AP1: EMP 0547 | AT1: EMP 1829 | AX1: EMP 1836 | BB1: EMP 2795 | BF1: EMP 0673
B3: Gross pay | D3: 125170 | F3: Gross pay | H3: ='Pension Computation'!F4 -> 186340 | J3: Gross pay | L3: ='Pension Computation'!F5 -> 290950 | N3: Gross pay | P3: 64790 | R3: Basic Pay | T3: ='Pension Computation'!D7 -> 333243.9 | V3: Basic Pay | X3: 220000 | Z3: Basic Pay | AB3: ='Pension Computation'!D9 -> 426250 | AD3: Basic Pay | AF3: ='Pension Computation'!D10 -> 580000 | AH3: Basic Pay | AJ3: ='Pension Computation'!D11 -> 255750 | AL3: Basic Pay | AN3: ='Pension Computation'!D12 -> 426250 | AP3: Basic Pay | AR3: ='Pension Computation'!D13 -> 350000 | AT3: Basic Pay | AV3: ='Pension Computation'!D14 -> 333243.9 | AX3: Basic Pay | AZ3: 727750 | BB3: Basic Pay | BD3: 38500 | BF3: Basic Pay | BH3: 693564
B4: Add: Allowances | F4: Add: Allowances | J4: Add: Allowances | N4: Add: Allowances | R4: Add: Allowances | V4: Add: Allowances | Z4: Add: Allowances | AD4: Add: Allowances | AH4: Add: Allowances | AL4: Add: Allowances | AP4: Add: Allowances | AT4: Add: Allowances | AX4: Add: Allowances | BB4: Add: Allowances | BF4: Add: Allowances
B5: Fuel Allowance | D5: 0 | F5: Fuel Allowance | H5: 0 | J5: Fuel Allowance | L5: 0 | N5: Fuel Allowance | P5: 0 | R5: Fuel Allowance | T5: 15000 | V5: Fuel Allowance | X5: 0 | Z5: Fuel Allowance | AB5: 20000 | AD5: Fuel Allowance | AF5: 20000 | AH5: Fuel Allowance | AJ5: 15000 | AL5: Fuel Allowance | AN5: 20000 | AP5: Fuel Allowance | AR5: 15000 | AT5: Fuel Allowance | AV5: 15000 | AX5: Fuel Allowance | AZ5: 50000 | BB5: Fuel Allowance | BD5: 0 | BF5: Fuel Allowance | BH5: 20000
B6: House Allowance | D6: 0 | F6: House Allowance | H6: 0 | J6: House Allowance | L6: 0 | N6: House Allowance | P6: 0 | R6: House Allowance | T6: 33324 | V6: House Allowance | X6: 0 | Z6: House Allowance | AB6: 42625 | AD6: House Allowance | AF6: 58000 | AH6: House Allowance | AJ6: 25575 | AL6: House Allowance | AN6: 42625 | AP6: House Allowance | AR6: 35000 | AT6: House Allowance | AV6: 33324 | AX6: House Allowance | AZ6: 72775 | BB6: House Allowance | BD6: 0 | BF6: House Allowance | BH6: 69356
B7: Acting Allowance | D7: 0 | F7: Acting Allowance | H7: 0 | J7: Acting Allowance | L7: 0 | N7: Acting Allowance | P7: 0 | R7: Acting Allowance | T7: 0 | V7: Acting Allowance | X7: 0 | Z7: Acting Allowance | AB7: 194170 | AD7: Acting Allowance | AF7: 0 | AH7: Acting Allowance | AJ7: 0 | AL7: Acting Allowance | AN7: 0 | AP7: Acting Allowance | AT7: Acting Allowance | AV7: 124540 | AX7: Acting Allowance | AZ7: 0 | BB7: Acting Allowance | BD7: 0 | BF7: Acting Allowance | BH7: 0
B8: Gross Pay | D8: =SUM(D3:D7) -> 125170 | F8: Gross Pay | H8: =SUM(H3:H7) -> 186340 | J8: Gross Pay | L8: =SUM(L3:L7) -> 290950 | N8: Gross Pay | P8: =SUM(P3:P7) -> 64790 | R8: Gross Pay | T8: =SUM(T3:T7) -> 381567.9 | V8: Gross Pay | X8: =SUM(X3:X7) -> 220000 | Z8: Gross Pay | AB8: =SUM(AB3:AB7) -> 683045 | AD8: Gross Pay | AF8: =SUM(AF3:AF7) -> 658000 | AH8: Gross Pay | AJ8: =SUM(AJ3:AJ7) -> 296325 | AL8: Gross Pay | AN8: =SUM(AN3:AN7) -> 488875 | AP8: Gross Pay | AR8: =SUM(AR3:AR7) -> 400000 | AT8: Gross Pay | AV8: =SUM(AV3:AV7) -> 506107.9 | AX8: Gross Pay | AZ8: =SUM(AZ3:AZ7) -> 850525 | BB8: Gross Pay | BD8: =SUM(BD3:BD7) -> 38500 | BF8: Gross Pay | BH8: =SUM(BH3:BH7) -> 782920
B10: Less: Allowable Deductions | F10: Less: Allowable Deductions | J10: Less: Allowable Deductions | N10: Less: Allowable Deductions | R10: Less: Allowable Deductions | V10: Less: Allowable Deductions | Z10: Less: Allowable Deductions | AD10: Less: Allowable Deductions | AH10: Less: Allowable Deductions | AL10: Less: Allowable Deductions | AP10: Less: Allowable Deductions | AT10: Less: Allowable Deductions | AX10: Less: Allowable Deductions | BB10: Less: Allowable Deductions | BF10: Less: Allowable Deductions
B11: NSSF Tier 1 | D11: =-IF(D8>9000,9000*6%,D8*6%) -> -540 | F11: NSSF Tier 1 | H11: =-IF(H8>9000,9000*6%,H8*6%) -> -540 | J11: NSSF Tier 1 | L11: =-IF(L8>9000,9000*6%,L8*6%) -> -540 | N11: NSSF Tier 1 | P11: =-IF(P8>9000,9000*6%,P8*6%) -> -540 | R11: NSSF Tier 1 | T11: =-IF(T8>9000,9000*6%,T8*6%) -> -540 | V11: NSSF Tier 1 | X11: =-IF(X8>9000,9000*6%,X8*6%) -> -540 | Z11: NSSF Tier 1 | AB11: =-IF(AB8>9000,9000*6%,AB8*6%) -> -540 | AD11: NSSF Tier 1 | AF11: =-IF(AF8>9000,9000*6%,AF8*6%) -> -540 | AH11: NSSF Tier 1 | AJ11: =-IF(AJ8>9000,9000*6%,AJ8*6%) -> -540 | AL11: NSSF Tier 1 | AN11: =-IF(AN8>9000,9000*6%,AN8*6%) -> -540 | AP11: NSSF Tier 1 | AR11: =-IF(AR8>9000,9000*6%,AR8*6%) -> -540 | AT11: NSSF Tier 1 | AV11: =-IF(AV8>9000,9000*6%,AV8*6%) -> -540 | AX11: NSSF Tier 1 | AZ11: =-IF(AZ8>9000,9000*6%,AZ8*6%) -> -540 | BB11: NSSF Tier 1 | BD11: =-IF(BD8>9000,9000*6%,BD8*6%) -> -540 | BF11: NSSF Tier 1 | BH11: =-IF(BH8>9000,9000*6%,BH8*6%) -> -540
B12: NSSF Tier 2 | D12: =-IF(D8>99000,99000*6%,D8*6%-540) -> -5940 | F12: NSSF Tier 2 | H12: =-IF(H8>99000,99000*6%,H8*6%-540) -> -5940 | J12: NSSF Tier 2 | L12: =-IF(L8>99000,99000*6%,L8*6%-540) -> -5940 | N12: NSSF Tier 2 | P12: =-IF(P8>99000,99000*6%,P8*6%-540) -> -3347.4 | R12: NSSF Tier 2 | T12: =-IF(T8>99000,99000*6%,T8*6%-540) -> -5940 | V12: NSSF Tier 2 | X12: =-IF(X8>99000,99000*6%,X8*6%-540) -> -5940 | Z12: NSSF Tier 2 | AB12: =-IF(AB8>99000,99000*6%,AB8*6%-540) -> -5940 | AD12: NSSF Tier 2 | AF12: =-IF(AF8>99000,99000*6%,AF8*6%-540) -> -5940 | AH12: NSSF Tier 2 | AJ12: =-IF(AJ8>99000,99000*6%,AJ8*6%-540) -> -5940 | AL12: NSSF Tier 2 | AN12: =-IF(AN8>99000,99000*6%,AN8*6%-540) -> -5940 | AP12: NSSF Tier 2 | AR12: =-IF(AR8>99000,99000*6%,AR8*6%-540) -> -5940 | AT12: NSSF Tier 2 | AV12: =-IF(AV8>99000,99000*6%,AV8*6%-540) -> -5940 | AX12: NSSF Tier 2 | AZ12: =-IF(AZ8>99000,99000*6%,AZ8*6%-540) -> -5940 | BB12: NSSF Tier 2 | BD12: =-IF(BD8>99000,99000*6%,BD8*6%-540) -> -1770 | BF12: NSSF Tier 2 | BH12: =-IF(BH8>99000,99000*6%,BH8*6%-540) -> -5940
B13: SHIF | D13: =-2.75%*D8 -> -3442.175 | F13: SHIF | H13: =-2.75%*H8 -> -5124.35 | J13: SHIF | L13: =-2.75%*L3 -> -8001.125 | N13: SHIF | P13: =-2.75%*P3 -> -1781.725 | R13: SHIF | T13: =-T8*2.75% -> -10493.117 | V13: SHIF | X13: =-X8*2.75% -> -6050 | Z13: SHIF | AB13: =-SUM(AB3:AB6)*2.75% -> -13444.062 | AD13: SHIF | AF13: =-AF8*2.75% -> -18095 | AH13: SHIF | AJ13: =-AJ8*2.75% -> -8148.9375 | AL13: SHIF | AN13: =-AN8*2.75% -> -13444.062 | AP13: SHIF | AR13: =-AR8*2.75% -> -11000 | AT13: SHIF | AV13: =-SUM(AV3:AV6)*2.75% -> -10493.117 | AX13: SHIF | AZ13: =-AZ8*2.75% -> -23389.438 | BB13: SHIF | BD13: =-BD8*2.75% -> -1058.75 | BF13: SHIF | BH13: =-BH8*2.75% -> -21530.3
B14: Pension | D14: =-5%*D8 -> -6258.5 | F14: Pension | H14: =-5%*H8 -> -9317 | J14: Pension | L14: =-5%*L3 -> -14547.5 | N14: Pension | P14: =-5%*P3 -> -3239.5 | R14: Pension | T14: =-5%*T3 -> -16662.195 | V14: Pension | X14: =-5%*X3 -> -11000 | Z14: Pension | AB14: =-5%*AB3 -> -21312.5 | AD14: Pension | AF14: =-5%*AF3 -> -29000 | AH14: Pension | AJ14: =-AJ3*5% -> -12787.5 | AL14: Pension | AN14: =-AN3*5% -> -21312.5 | AP14: Pension | AR14: =-AR3*5% -> -17500 | AT14: Pension | AV14: =-AV3*5% -> -16662.195 | AX14: Pension | AZ14: =-AZ3*5% -> -36387.5 | BB14: Pension | BD14: =-BD3*5% -> -1925 | BF14: Pension | BH14: =-BH3*5% -> -34678.2
B15: AHL | D15: =-1.5%*D8 -> -1877.55 | F15: AHL | H15: =-1.5%*H8 -> -2795.1 | J15: AHL | L15: =-1.5%*L3 -> -4364.25 | N15: AHL | P15: =-1.5%*P3 -> -971.85 | R15: AHL | T15: =-1.5%*T8 -> -5723.5185 | V15: AHL | X15: =-1.5%*X8 -> -3300 | Z15: AHL | AB15: =-AB8*1.5% -> -10245.675 | AD15: AHL | AF15: =-AF8*1.5% -> -9870 | AH15: AHL | AJ15: =-AJ8*1.5% -> -4444.875 | AL15: AHL | AN15: =-AN8*1.5% -> -7333.125 | AP15: AHL | AR15: =-AR8*1.5% -> -6000 | AT15: AHL | AV15: =-AV8*1.5% -> -7591.6185 | AX15: AHL | AZ15: =-AZ8*1.5% -> -12757.875 | BB15: AHL | BD15: =-BD8*1.5% -> -577.5 | BF15: AHL | BH15: =-BH8*1.5% -> -11743.8
B16: Taxable pay | D16: =SUM(D8:D15) -> 107111.77 | F16: Taxable pay | H16: =SUM(H8:H15) -> 162623.55 | J16: Taxable pay | L16: =SUM(L8:L15) -> 257557.12 | N16: Taxable pay | P16: =SUM(P5:P15) -> 54909.525 | R16: Taxable pay | T16: =SUM(T8:T15) -> 342209.07 | V16: Taxable pay | X16: =SUM(X8:X15) -> 193170 | Z16: Taxable pay | AB16: =SUM(AB8:AB15) -> 631562.76 | AD16: Taxable pay | AF16: =SUM(AF8:AF15) -> 594555 | AH16: Taxable pay | AJ16: =SUM(AJ8:AJ15) -> 264463.69 | AL16: Taxable pay | AN16: =SUM(AN8:AN15) -> 440305.31 | AP16: Taxable pay | AR16: =SUM(AR8:AR15) -> 359020 | AT16: Taxable pay | AV16: =SUM(AV8:AV15) -> 464880.97 | AX16: Taxable pay | AZ16: =SUM(AZ8:AZ15) -> 771510.19 | BB16: Taxable pay | BD16: =SUM(BD8:BD15) -> 32628.75 | BF16: Taxable pay | BH16: =SUM(BH8:BH15) -> 708487.7
B17: School Fee | D17: 0 | F17: School Fee | H17: 0 | J17: School Fee | L17: 0 | N17: School Fee | P17: 0 | R17: School Fee | T17: 80000 | V17: School Fee | X17: 0 | Z17: School Fee | AB17: 27277 | AD17: School Fee | AF17: 149333 | AH17: School Fee | AJ17: 120000 | AL17: School Fee | AN17: 0 | AP17: School Fee | AR17: 0 | AT17: School Fee | AV17: 0 | AX17: School Fee | AZ17: 0 | BB17: School Fee | BD17: 0 | BF17: School Fee | BH17: 66666
B18: Adjusted Taxable Pay | D18: =SUM(D16:D17) -> 107111.77 | F18: Adjusted Taxable Pay | H18: =SUM(H16:H17) -> 162623.55 | J18: Adjusted Taxable Pay | L18: =SUM(L16:L17) -> 257557.12 | N18: Adjusted Taxable Pay | P18: =SUM(P16:P17) -> 54909.525 | R18: Adjusted Taxable Pay | T18: =SUM(T16:T17) -> 422209.07 | V18: Adjusted Taxable Pay | X18: =SUM(X16:X17) -> 193170 | Z18: Adjusted Taxable Pay | AB18: =SUM(AB16:AB17) -> 658839.76 | AD18: Adjusted Taxable Pay | AF18: =SUM(AF16:AF17) -> 743888 | AH18: Adjusted Taxable Pay | AJ18: =SUM(AJ16:AJ17) -> 384463.69 | AL18: Adjusted Taxable Pay | AN18: =SUM(AN16:AN17) -> 440305.31 | AP18: Adjusted Taxable Pay | AR18: =SUM(AR16:AR17) -> 359020 | AT18: Adjusted Taxable Pay | AV18: =SUM(AV16:AV17) -> 464880.97 | AX18: Adjusted Taxable Pay | AZ18: =SUM(AZ16:AZ17) -> 771510.19 | BB18: Adjusted Taxable Pay | BD18: =SUM(BD16:BD17) -> 32628.75 | BF18: Adjusted Taxable Pay | BH18: =SUM(BH16:BH17) -> 775153.7
B20: Graduated scale rate | F20: Graduated scale rate | J20: Graduated scale rate | N20: Graduated scale rate | R20: Graduated scale rate | V20: Graduated scale rate | Z20: Graduated scale rate | AD20: Graduated scale rate | AH20: Graduated scale rate | AL20: Graduated scale rate | AP20: Graduated scale rate | AT20: Graduated scale rate | AX20: Graduated scale rate | BB20: Graduated scale rate | BF20: Graduated scale rate
B21: 0 to 24,0000 | C21: 0.1 | D21: =-24000*C21 -> -2400 | F21: 0 to 24,0000 | G21: 0.1 | H21: =-24000*G21 -> -2400 | J21: 0 to 24,0000 | K21: 0.1 | L21: =-24000*K21 -> -2400 | N21: 0 to 24,0000 | O21: 0.1 | P21: =-24000*O21 -> -2400 | R21: 0 to 24,0000 | S21: 0.1 | T21: =-24000*S21 -> -2400 | V21: 0 to 24,0000 | W21: 0.1 | X21: =-24000*W21 -> -2400 | Z21: 0 to 24,0000 | AA21: 0.1 | AB21: =-24000*AA21 -> -2400 | AD21: 0 to 24,0000 | AE21: 0.1 | AF21: =-24000*AE21 -> -2400 | AH21: 0 to 24,0000 | AI21: 0.1 | AJ21: =-24000*AI21 -> -2400 | AL21: 0 to 24,0000 | AM21: 0.1 | AN21: =-24000*AM21 -> -2400 | AP21: 0 to 24,0000 | AQ21: 0.1 | AR21: =-24000*AQ21 -> -2400 | AT21: 0 to 24,0000 | AU21: 0.1 | AV21: =-24000*AU21 -> -2400 | AX21: 0 to 24,0000 | AY21: 0.1 | AZ21: =-24000*AY21 -> -2400 | BB21: 0 to 24,0000 | BC21: 0.1 | BD21: =-24000*BC21 -> -2400 | BF21: 0 to 24,0000 | BG21: 0.1 | BH21: =-24000*BG21 -> -2400
B22: Next 8,333 | C22: =25% -> 0.25 | D22: =-8333*C22 -> -2083.25 | F22: Next 8,333 | G22: =25% -> 0.25 | H22: =-8333*G22 -> -2083.25 | J22: Next 8,333 | K22: =25% -> 0.25 | L22: =-8333*K22 -> -2083.25 | N22: Next 8,333 | O22: =25% -> 0.25 | P22: =-8333*O22 -> -2083.25 | R22: Next 8,333 | S22: =25% -> 0.25 | T22: =-8333*S22 -> -2083.25 | V22: Next 8,333 | W22: =25% -> 0.25 | X22: =-8333*W22 -> -2083.25 | Z22: Next 8,333 | AA22: =25% -> 0.25 | AB22: =-8333*AA22 -> -2083.25 | AD22: Next 8,333 | AE22: =25% -> 0.25 | AF22: =-8333*AE22 -> -2083.25 | AH22: Next 8,333 | AI22: =25% -> 0.25 | AJ22: =-8333*AI22 -> -2083.25 | AL22: Next 8,333 | AM22: =25% -> 0.25 | AN22: =-8333*AM22 -> -2083.25 | AP22: Next 8,333 | AQ22: =25% -> 0.25 | AR22: =-8333*AQ22 -> -2083.25 | AT22: Next 8,333 | AU22: =25% -> 0.25 | AV22: =-8333*AU22 -> -2083.25 | AX22: Next 8,333 | AY22: =25% -> 0.25 | AZ22: =-8333*AY22 -> -2083.25 | BB22: Next 8,333 | BC22: =25% -> 0.25 | BD22: =-(BD18-24000)*BC22 -> -2157.1875 | BF22: Next 8,333 | BG22: =25% -> 0.25 | BH22: =-8333*BG22 -> -2083.25
B23: Next 467,667 | C23: 0.3 | D23: =-(D18-24000-8333)*30% -> -22433.632 | F23: Next 467,667 | G23: 0.3 | H23: =-(H18-24000-8333)*30% -> -39087.165 | J23: Next 467,667 | K23: 0.3 | L23: =-(L16-24000-8333)*30% -> -67567.238 | N23: Next 467,667 | O23: 0.3 | P23: =-(P18-24000-8333)*30% -> -6772.9575 | R23: Next 467,667 | S23: 0.3 | T23: =-(T18-24000-8333)*30% -> -116962.82 | V23: Next 467,667 | W23: 0.3 | X23: =-(X16-24000-8333)*30% -> -48251.1 | Z23: Next 467,667 | AA23: 0.3 | AB23: =-467667*AA23 -> -140300.1 | AD23: Next 467,667 | AE23: 0.3 | AF23: =-467667*30% -> -140300.1 | AH23: Next 467,667 | AI23: 0.3 | AJ23: =-(AJ18-8333-24000)*AI23 -> -105639.21 | AL23: Next 467,667 | AM23: 0.3 | AN23: =-(AN18-24000-8333)*30% -> -122391.69 | AP23: Next 467,667 | AQ23: 0.3 | AR23: =-(AR16-24000-8333)*30% -> -98006.1 | AT23: Next 467,667 | AU23: 0.3 | AV23: =-(AV16-24000-8333)*30% -> -129764.39 | AX23: Next 467,667 | AY23: 0.3 | AZ23: =-467667*AY23 -> -140300.1 | BB23: Next 467,667 | BC23: 0.3 | BD23: 0 | BF23: Next 467,667 | BG23: 0.3 | BH23: =-467667*BG23 -> -140300.1
B24: Relief | D24: 2400 | F24: Relief | H24: 2400 | J24: Relief | L24: 2400 | N24: Relief | P24: 2400 | R24: Next 300,000 | S24: 0.325 | T24: 0 | V24: Next 300,000 | W24: 0.325 | X24: 0 | Z24: Next 300,000 | AA24: 0.325 | AB24: =-(AB18-500000)*AA24 -> -51622.923 | AD24: Next 300,000 | AE24: 0.325 | AF24: =-(AF18-500000)*AE24 -> -79263.6 | AH24: Next 300,000 | AI24: 0.325 | AJ24: 0 | AL24: Next 300,000 | AM24: 0.325 | AN24: 0 | AP24: Next 300,000 | AQ24: 0.325 | AR24: 0 | AT24: Next 300,000 | AU24: 0.325 | AV24: 0 | AX24: Next 300,000 | AY24: 0.325 | AZ24: =-(AZ18-500000)*AY24 -> -88240.811 | BB24: Next 300,000 | BC24: 0.325 | BD24: 0 | BF24: Next 300,000 | BG24: 0.325 | BH24: =-(BH18-500000)*BG24 -> -89424.952
B25: PAYE | D25: =SUM(D21:D24) -> -24516.882 | F25: PAYE | H25: =SUM(H21:H24) -> -41170.415 | J25: PAYE | L25: =SUM(L21:L24) -> -69650.488 | N25: PAYE | P25: =SUM(P21:P24) -> -8856.2075 | R25: Relief | T25: 2400 | V25: Relief | X25: 2400 | Z25: Relief | AB25: 2400 | AD25: Relief | AF25: 2400 | AH25: Relief | AJ25: 2400 | AL25: Relief | AN25: 2400 | AP25: Relief | AR25: 2400 | AT25: Relief | AV25: 2400 | AX25: Relief | AZ25: 2400 | BB25: Relief | BD25: 2400 | BF25: Relief | BH25: 2400
R26: PAYE | T26: =SUM(T21:T25) -> -119046.07 | V26: PAYE | X26: =SUM(X21:X25) -> -50334.35 | Z26: PAYE | AB26: =SUM(AB21:AB25) -> -194006.27 | AD26: PAYE | AF26: =SUM(AF21:AF25) -> -221646.95 | AH26: PAYE | AJ26: =SUM(AJ21:AJ25) -> -107722.46 | AL26: PAYE | AN26: =SUM(AN21:AN25) -> -124474.94 | AP26: PAYE | AR26: =SUM(AR21:AR25) -> -100089.35 | AT26: PAYE | AV26: =SUM(AV21:AV25) -> -131847.64 | AX26: PAYE | AZ26: =SUM(AZ21:AZ25) -> -230624.16 | BB26: PAYE | BD26: =SUM(BD21:BD25) -> -2157.1875 | BF26: PAYE | BH26: =SUM(BH21:BH25) -> -231808.3
B27: Welfare | D27: -400 | F27: Welfare | H27: -400 | J27: Welfare | L27: -400 | N27: Welfare | P27: -400
B28: Excess Pension | D28: =-'Pension Computation'!N3*30% -> -520.65 | F28: Excess Pension | H28: =-'Pension Computation'!N4*30% -> -3273.3 | J28: Excess Pension | L28: =-'Pension Computation'!N5*30% -> -7980.75 | N28: Tax on excess pension | P28: =-'Pension Computation'!R5*30% -> 0 | R28: Welfare | T28: -400 | V28: Welfare | X28: -400 | Z28: Welfare | AB28: -400 | AD28: Welfare | AF28: -400 | AH28: Welfare | AJ28: -400 | AL28: Welfare | AN28: -400 | AP28: Welfare | AR28: -400 | AT28: Welfare | AV28: -400 | AX28: Welfare | AZ28: -400 | BB28: Welfare | BD28: -400 | BF28: Welfare | BH28: -400
B29: SACCO | D29: =-10200 -> -10200 | F29: SACCO | H29: 0 | J29: SACCO | L29: =-(61445) -> -61445 | N29: SACCO | P29: -24268 | R29: Tax on excess pension | T29: -9883.98 | V29: Utu Power | X29: -100 | Z29: Tax on excess pension | AB29: -15241.69 | AD29: Tax on excess pension | AF29: -22737 | AH29: Tax on excess pension | AJ29: -6396.75 | AL29: Tax on excess pension | AN29: =-14069.25 -> -14069.25 | AP29: Tax on excess pension | AR29: -10638 | AT29: Tax on excess pension | AV29: =-9883.98 -> -9883.98 | AX29: Tax on excess pension | AZ29: -29939.82 | BB29: Tax on excess pension | BD29: 0 | BF29: Tax on excess pension | BH29: -28273.25
B30: UTU Power | D30: 0 | F30: UTU Power | H30: 0 | J30: UTU Power | L30: 0 | N30: UTU Power | P30: -200 | R30: SACCO | T30: =-(110745) -> -110745 | V30: SACCO | X30: -57720 | Z30: SACCO | AB30: -156900 | AD30: SACCO | AF30: 0 | AH30: SACCO | AJ30: -31855 | AL30: SACCO | AN30: -10000 | AP30: SACCO | AR30: -50200 | AT30: SACCO | AV30: -97369 | AX30: SACCO | AZ30: 0 | BB30: SACCO | BD30: 0 | BF30: SACCO | BH30: -151870
B31: Net pay | D31: =D16+SUM(D25:D30) -> 71474.242 | F31: Net pay | H31: =H16+SUM(H25:H30) -> 117779.83 | J31: Net pay | L31: =L16+SUM(L25:L30) -> 118080.89 | N31: Net pay | P31: =P16+SUM(P25:P30) -> 21185.317 | R31: UTU Power | T31: 0 | V31: Tax on excess pension | X31: =-'Pension Computation'!N8*30% -> -4788 | Z31: UTU Power | AB31: 0 | AD31: UTU Power | AF31: 0 | AH31: School Fees | AJ31: 0 | AL31: School Fees | AP31: Catering | AR31: -5000 | AT31: Catering | AV31: 0 | AX31: Catering | AZ31: 0 | BB31: Catering | BD31: 0 | BF31: Catering | BH31: 0
R32: Net pay | T32: =T16+SUM(T26:T31) -> 102134.02 | V32: Net pay | X32: =X16+SUM(X26:X31) -> 79827.65 | Z32: Net pay | AB32: =AB16+SUM(AB26:AB31) -> 265014.8 | AD32: Net pay | AF32: =AF16+SUM(AF26:AF31) -> 349771.05 | AH32: Net pay | AJ32: =AJ16+SUM(AJ26:AJ31) -> 118089.48 | AL32: Net pay | AN32: =AN16+SUM(AN26:AN31) -> 291361.12 | AP32: Net pay | AR32: =AR16+SUM(AR26:AR31) -> 192692.65 | AT32: Net pay | AV32: =AV16+SUM(AV26:AV31) -> 225380.35 | AX32: Net pay | AZ32: =AZ16+SUM(AZ26:AZ31) -> 510546.21 | BB32: Net pay | BD32: =BD16+SUM(BD26:BD31) -> 30071.562 | BF32: Net pay | BH32: =BH16+SUM(BH26:BH31) -> 296136.15
B34: RECOMPUTATIONS
B36: Basic Pay | D36: 125170 | F36: Basic Pay | H36: ='Pension Computation'!D4 -> 186340 | J36: Basic Pay | L36: ='Pension Computation'!D5 -> 290950 | N36: Basic Pay | P36: =P3 -> 64790 | R36: Basic Pay | T36: =T3 -> 333243.9 | V36: Basic Pay | X36: 220000 | Z36: Basic Pay | AB36: 426250 | AD36: Basic Pay | AF36: 580000 | AH36: Basic Pay | AJ36: 255750 | AL36: Basic Pay | AN36: 426250 | AP36: Basic Pay | AR36: 350000 | AT36: Basic Pay | AV36: 333243.9 | AX36: Basic Pay | AZ36: =AZ3 -> 727750 | BB36: Basic Pay | BD36: =BD3 -> 38500 | BF36: Basic Pay | BH36: =BH3 -> 693564
B37: Add: Allowances | F37: Add: Allowances | J37: Add: Allowances | N37: Add: Allowances | R37: Add: Allowances | V37: Add: Allowances | Z37: Add: Allowances | AD37: Add: Allowances | AH37: Add: Allowances | AL37: Add: Allowances | AP37: Add: Allowances | AT37: Add: Allowances | AX37: Add: Allowances | BB37: Add: Allowances | BF37: Add: Allowances
B38: Fuel Allowance | D38: 0 | F38: Fuel Allowance | H38: 0 | J38: Fuel Allowance | L38: 0 | N38: Fuel Allowance | P38: 0 | R38: Fuel Allowance | T38: 15000 | V38: Fuel Allowance | X38: 0 | Z38: Fuel Allowance | AB38: 20000 | AD38: Fuel Allowance | AF38: 20000 | AH38: Fuel Allowance | AJ38: 15000 | AL38: Fuel Allowance | AN38: 20000 | AP38: Fuel Allowance | AR38: 15000 | AT38: Fuel Allowance | AV38: 15000 | AX38: Fuel Allowance | AZ38: =AZ5 -> 50000 | BB38: Fuel Allowance | BD38: =BD5 -> 0 | BF38: Fuel Allowance | BH38: =BH5 -> 20000
B39: House Allowance | D39: 0 | F39: House Allowance | H39: 0 | J39: House Allowance | L39: 0 | N39: House Allowance | P39: 0 | R39: House Allowance | T39: 33324 | V39: House Allowance | X39: =X4 -> 0 | Z39: House Allowance | AB39: 42625 | AD39: House Allowance | AF39: 58000 | AH39: House Allowance | AJ39: 25575 | AL39: House Allowance | AN39: 42625 | AP39: House Allowance | AR39: 35000 | AT39: House Allowance | AV39: 33324 | AX39: House Allowance | AZ39: =AZ6 -> 72775 | BB39: House Allowance | BD39: =BD6 -> 0 | BF39: House Allowance | BH39: =BH6 -> 69356
B40: Acting Allowance | D40: 0 | F40: Acting Allowance | H40: 0 | J40: Acting Allowance | L40: 0 | N40: Acting Allowance | P40: 0 | R40: Acting Allowance | T40: 0 | V40: Acting Allowance | X40: 0 | Z40: Acting Allowance | AB40: 194170 | AD40: Acting Allowance | AF40: 0 | AH40: Acting Allowance | AJ40: 0 | AL40: Acting Allowance | AN40: 0 | AP40: Acting Allowance | AR40: 0 | AT40: Acting Allowance | AV40: 124540 | AX40: Acting Allowance | AZ40: =AZ7 -> 0 | BB40: Acting Allowance | BD40: =BD7 -> 0 | BF40: Acting Allowance | BH40: =BH7 -> 0
B41: Gross Pay | D41: =SUM(D36:D40) -> 125170 | F41: Gross Pay | H41: =SUM(H36:H40) -> 186340 | J41: Gross Pay | L41: =SUM(L36:L40) -> 290950 | N41: Gross Pay | P41: =SUM(P36:P40) -> 64790 | R41: Gross Pay | T41: =SUM(T36:T40) -> 381567.9 | V41: Gross Pay | X41: =SUM(X36:X40) -> 220000 | Z41: Gross Pay | AB41: =SUM(AB36:AB40) -> 683045 | AD41: Gross Pay | AF41: =SUM(AF36:AF40) -> 658000 | AH41: Gross Pay | AJ41: =SUM(AJ36:AJ40) -> 296325 | AL41: Gross Pay | AN41: =SUM(AN36:AN40) -> 488875 | AP41: Gross Pay | AR41: =SUM(AR36:AR40) -> 400000 | AT41: Gross Pay | AV41: =SUM(AV36:AV40) -> 506107.9 | AX41: Gross Pay | AZ41: =SUM(AZ36:AZ40) -> 850525 | BB41: Gross Pay | BD41: =SUM(BD36:BD40) -> 38500 | BF41: Gross Pay | BH41: =SUM(BH36:BH40) -> 782920
B43: Less: Allowable Deductions | F43: Less: Allowable Deductions | J43: Less: Allowable Deductions
B44: NSSF Tier 1 | D44: =-IF(D41>9000,9000*6%,E41*6%) -> -540 | F44: NSSF Tier 1 | H44: =-IF(H41>9000,9000*6%,I41*6%) -> -540 | J44: NSSF Tier 1 | L44: =-IF(L41>9000,9000*6%,M41*6%) -> -540 | N44: Less: Allowable Deductions | R44: Less: Allowable Deductions | V44: Less: Allowable Deductions | Z44: Less: Allowable Deductions | AD44: Less: Allowable Deductions | AH44: Less: Allowable Deductions | AL44: Less: Allowable Deductions | AP44: Less: Allowable Deductions | AT44: Less: Allowable Deductions | AX44: Less: Allowable Deductions | BB44: Less: Allowable Deductions | BF44: Less: Allowable Deductions
B45: NSSF Tier 2 | D45: =-IF(D41>99000,99000*6%,D41*6%-540) -> -5940 | F45: NSSF Tier 2 | H45: =-IF(H41>99000,99000*6%,H41*6%-540) -> -5940 | J45: NSSF Tier 2 | L45: =-IF(L41>99000,99000*6%,L41*6%-540) -> -5940 | N45: NSSF Tier 1 | P45: =-IF(P41>9000,9000*6%,Q41*6%) -> -540 | R45: NSSF Tier 1 | T45: =-IF(T41>9000,540,6%*T41) -> -540 | V45: NSSF Tier 1 | X45: =-IF(X41>9000,540,6%*X41) -> -540 | Z45: NSSF Tier 1 | AB45: =-IF(AB41>9000,540,6%*AB41) -> -540 | AD45: NSSF Tier 1 | AF45: =-IF(AF41>9000,540,6%*AF41) -> -540 | AH45: NSSF Tier 1 | AJ45: =-IF(AJ41>9000,540,6%*AJ41) -> -540 | AL45: NSSF Tier 1 | AN45: =-IF(AN41>9000,540,6%*AN41) -> -540 | AP45: NSSF Tier 1 | AR45: =-IF(AR41>9000,540,6%*AR41) -> -540 | AT45: NSSF Tier 1 | AV45: =-IF(AV41>9000,540,6%*AV41) -> -540 | AX45: NSSF Tier 1 | AZ45: =-IF(AZ41>9000,540,6%*AZ41) -> -540 | BB45: NSSF Tier 1 | BD45: =-IF(BD41>9000,540,6%*BD41) -> -540 | BF45: NSSF Tier 1 | BH45: =-IF(BH41>9000,540,6%*BH41) -> -540
B46: SHIF | D46: =-2.75%*D41 -> -3442.175 | F46: SHIF | H46: =-2.75%*H41 -> -5124.35 | J46: SHIF | L46: =-2.75%*L41 -> -8001.125 | N46: NSSF Tier 2 | P46: =-IF(P41>99000,99000*6%,P41*6%-540) -> -3347.4 | R46: NSSF Tier 2 | T46: =-IF(T41>99000,99000*6%,T41*6%-540) -> -5940 | V46: NSSF Tier 2 | X46: =-IF(X41>99000,99000*6%,X41*6%-540) -> -5940 | Z46: NSSF Tier 2 | AB46: =-IF(AB41>99000,99000*6%,AB41*6%-540) -> -5940 | AD46: NSSF Tier 2 | AF46: =-IF(AF41>99000,99000*6%,AF41*6%-540) -> -5940 | AH46: NSSF Tier 2 | AJ46: =-IF(AJ41>99000,99000*6%,AJ41*6%-540) -> -5940 | AL46: NSSF Tier 2 | AN46: =-IF(AN41>99000,99000*6%,AN41*6%-540) -> -5940 | AP46: NSSF Tier 2 | AR46: =-IF(AR41>99000,99000*6%,AR41*6%-540) -> -5940 | AT46: NSSF Tier 2 | AV46: =-IF(AV41>99000,99000*6%,AV41*6%-540) -> -5940 | AX46: NSSF Tier 2 | AZ46: =-IF(AZ41>99000,99000*6%,AZ41*6%-540) -> -5940 | BB46: NSSF Tier 2 | BD46: =-IF(BD41>99000,99000*6%,BD41*6%-540) -> -1770 | BF46: NSSF Tier 2 | BH46: =-IF(BH41>99000,99000*6%,BH41*6%-540) -> -5940
...

Sheet Pension Computation
B1: TABLE A (KRCS PAYROLL) - What was calculated (Actuals)
B2: No. | C2: EMP. NO. | D2: Basic Pay | E2: Allowances | F2: Gross Pay | G2: NSSF Tier 1 Employee | H2: NSSF Tier 2 Employee | I2: NSSF (Employer) | J2: Pension (Employee)-5% | K2: Pension (Employer)-10% | L2: Total | M2: Limit | N2: Excess
B3: 1 | C3: EMP3866 | D3: 125170 | E3: 0 | F3: =D3+E3 -> 125170 | G3: =IF(D3>9000,9000*6%,D3*6%) -> 540 | H3: =IF(F3>99000,99000*6%,F3*6%-G3) -> 5940 | I3: =G3+H3 -> 6480 | J3: =5%*D3 -> 6258.5 | K3: =D3*10% -> 12517 | L3: =SUM(G3:K3) -> 31735.5 | M3: 30000 | N3: =IF(L3>M3,L3-M3,0) -> 1735.5
B4: 2 | C4: EMP004 | D4: 186340 | E4: 0 | F4: =D4+E4 -> 186340 | G4: =IF(D4>9000,9000*6%,D4*6%) -> 540 | H4: =IF(F4>99000,99000*6%,F4*6%-G4) -> 5940 | I4: =G4+H4 -> 6480 | J4: =5%*D4 -> 9317 | K4: =D4*10% -> 18634 | L4: =SUM(G4:K4) -> 40911 | M4: 30000 | N4: =IF(L4>M4,L4-M4,0) -> 10911
B5: 3 | C5: EMP040 | D5: 290950 | E5: 0 | F5: =D5+E5 -> 290950 | G5: =IF(D5>9000,9000*6%,D5*6%) -> 540 | H5: =IF(F5>99000,99000*6%,F5*6%-G5) -> 5940 | I5: =G5+H5 -> 6480 | J5: =5%*D5 -> 14547.5 | K5: =D5*10% -> 29095 | L5: =SUM(G5:K5) -> 56602.5 | M5: 30000 | N5: =IF(L5>M5,L5-M5,0) -> 26602.5
B6: 4 | C6: EMP0089 | D6: 64790 | E6: 0 | F6: =D6+E6 -> 64790 | G6: =IF(D6>9000,9000*6%,D6*6%) -> 540 | H6: =IF(F6>99000,99000*6%,F6*6%-G6) -> 3347.4 | I6: =G6+H6 -> 3887.4 | J6: =5%*D6 -> 3239.5 | K6: =D6*10% -> 6479 | L6: =SUM(G6:K6) -> 17493.3 | M6: 30000 | N6: =IF(L6>M6,L6-M6,0) -> 0
B7: 5 | C7: EMP0158 | D7: 333243.9 | E7: =15000+33324 -> 48324 | F7: =D7+E7 -> 381567.9 | G7: =IF(D7>9000,9000*6%,D7*6%) -> 540 | H7: =IF(F7>99000,99000*6%,F7*6%-G7) -> 5940 | I7: =G7+H7 -> 6480 | J7: =5%*D7 -> 16662.195 | K7: =D7*10% -> 33324.39 | L7: =SUM(G7:K7) -> 62946.585 | M7: 30000 | N7: =IF(L7>M7,L7-M7,0) -> 32946.585
B8: 6 | C8: EMP02024 | D8: 220000 | E8: 0 | F8: =D8+E8 -> 220000 | G8: =IF(D8>9000,9000*6%,D8*6%) -> 540 | H8: =IF(F8>99000,99000*6%,F8*6%-G8) -> 5940 | I8: =G8+H8 -> 6480 | J8: =5%*D8 -> 11000 | K8: =D8*10% -> 22000 | L8: =SUM(G8:K8) -> 45960 | M8: 30000 | N8: =IF(L8>M8,L8-M8,0) -> 15960
B9: 7 | C9: EMP0303 | D9: 426250 | E9: =(194170+20000+42625) -> 256795 | F9: =D9+E9 -> 683045 | G9: =IF(D9>9000,9000*6%,D9*6%) -> 540 | H9: =IF(F9>99000,99000*6%,F9*6%-G9) -> 5940 | I9: =G9+H9 -> 6480 | J9: =5%*D9 -> 21312.5 | K9: =D9*10% -> 42625 | L9: =SUM(G9:K9) -> 76897.5 | M9: 30000 | N9: =IF(L9>M9,L9-M9,0) -> 46897.5
B10: 8 | C10: EMP0495 | D10: 580000 | E10: =20000+58000 -> 78000 | F10: =D10+E10 -> 658000 | G10: =IF(D10>9000,9000*6%,D10*6%) -> 540 | H10: =IF(F10>99000,99000*6%,F10*6%-G10) -> 5940 | I10: =G10+H10 -> 6480 | J10: =5%*D10 -> 29000 | K10: =D10*10% -> 58000 | L10: =SUM(G10:K10) -> 99960 | M10: 30000 | N10: =IF(L10>M10,L10-M10,0) -> 69960
B11: 9 | C11: EMP0500 | D11: 255750 | E11: =15000+25575 -> 40575 | F11: =D11+E11 -> 296325 | G11: =IF(D11>9000,9000*6%,D11*6%) -> 540 | H11: =IF(F11>99000,99000*6%,F11*6%-G11) -> 5940 | I11: =G11+H11 -> 6480 | J11: =5%*D11 -> 12787.5 | K11: =D11*10% -> 25575 | L11: =SUM(G11:K11) -> 51322.5 | M11: 30000 | N11: =IF(L11>M11,L11-M11,0) -> 21322.5
B12: 10 | C12: EMP0525 | D12: 426250 | E12: =20000+42625 -> 62625 | F12: =D12+E12 -> 488875 | G12: =IF(D12>9000,9000*6%,D12*6%) -> 540 | H12: =IF(F12>99000,99000*6%,F12*6%-G12) -> 5940 | I12: =G12+H12 -> 6480 | J12: =5%*D12 -> 21312.5 | K12: =D12*10% -> 42625 | L12: =SUM(G12:K12) -> 76897.5 | M12: 30000 | N12: =IF(L12>M12,L12-M12,0) -> 46897.5
B13: 11 | C13: EMP0547 | D13: 350000 | E13: =15000+35000 -> 50000 | F13: =D13+E13 -> 400000 | G13: =IF(D13>9000,9000*6%,D13*6%) -> 540 | H13: =IF(F13>99000,99000*6%,F13*6%-G13) -> 5940 | I13: =G13+H13 -> 6480 | J13: =5%*D13 -> 17500 | K13: =D13*10% -> 35000 | L13: =SUM(G13:K13) -> 65460 | M13: 30000 | N13: =IF(L13>M13,L13-M13,0) -> 35460
B14: 12 | C14: EMP1829 | D14: 333243.9 | E14: =124540+15000+33324 -> 172864 | F14: =D14+E14 -> 506107.9 | G14: =IF(D14>9000,9000*6%,D14*6%) -> 540 | H14: =IF(F14>99000,99000*6%,F14*6%-G14) -> 5940 | I14: =G14+H14 -> 6480 | J14: =5%*D14 -> 16662.195 | K14: =D14*10% -> 33324.39 | L14: =SUM(G14:K14) -> 62946.585 | M14: 30000 | N14: =IF(L14>M14,L14-M14,0) -> 32946.585
B15: 13 | C15: EMP1836 | D15: 727500 | E15: =50000+72775 -> 122775 | F15: =D15+E15 -> 850275 | G15: =IF(D15>9000,9000*6%,D15*6%) -> 540 | H15: =IF(F15>99000,99000*6%,F15*6%-G15) -> 5940 | I15: =G15+H15 -> 6480 | J15: =5%*D15 -> 36375 | K15: =D15*10% -> 72750 | L15: =SUM(G15:K15) -> 122085 | M15: 30000 | N15: =IF(L15>M15,L15-M15,0) -> 92085
B16: 14 | C16: EMP2795 | D16: 38500 | E16: 0 | F16: =D16+E16 -> 38500 | G16: =IF(D16>9000,9000*6%,D16*6%) -> 540 | H16: =IF(F16>99000,99000*6%,F16*6%-G16) -> 1770 | I16: =G16+H16 -> 2310 | J16: =5%*D16 -> 1925 | K16: =D16*10% -> 3850 | L16: =SUM(G16:K16) -> 10395 | M16: 30000 | N16: =IF(L16>M16,L16-M16,0) -> 0
B17: 15 | C17: EMP0673 | D17: 693564 | E17: =20000+69356 -> 89356 | F17: =D17+E17 -> 782920 | G17: =IF(D17>9000,9000*6%,D17*6%) -> 540 | H17: =IF(F17>99000,99000*6%,F17*6%-G17) -> 5940 | I17: =G17+H17 -> 6480 | J17: =5%*D17 -> 34678.2 | K17: =D17*10% -> 69356.4 | L17: =SUM(G17:K17) -> 116994.6 | M17: 30000 | N17: =IF(L17>M17,L17-M17,0) -> 86994.6
D18: =SUM(D3:D17) -> 5051551.8 | E18: =SUM(E3:E17) -> 921314 | F18: =SUM(F3:F17) -> 5972865.8 | G18: =SUM(G3:G17) -> 8100 | H18: =SUM(H3:H17) -> 82337.4 | I18: =SUM(I3:I17) -> 90437.4 | J18: =SUM(J3:J17) -> 252577.59 | K18: =SUM(K3:K17) -> 505155.18 | ... N18: =SUM(N3:N17) -> 520719.27
L19: =SUM(G19:K19) -> 0
B20: TABLE B (RECOMPUTATION) - What Ought to be (Correct position)
B21: No. | C21: EMP. NO. | D21: Basic Pay | E21: Allowances | F21: Gross Pay | G21: NSSF Tier 1 Employee | H21: NSSF Tier 2 Employee | I21: NSSF (Employer) | J21: Pension (Employee)-5% of gross | K21: Pension (Employer)-10% of basic | L21: Total | M21: Limit | N21: Excess
B22: 1 | C22: EMP3866 | D22: =D3 -> 125170 | E22: =E3 -> 0 | F22: =F3 -> 125170 | G22: =G3 -> 540 | H22: =H3 -> 5940 | I22: =I3 -> 6480 | J22: =J3 -> 6258.5 | K22: =K3 -> 12517 | ... M22: =M3 -> 30000 | N22: =IF(L22>M22,L22-M22,0) -> 1735.5
B23: 2 | C23: EMP004 | D23: =D4 -> 186340 | E23: =E4 -> 0 | F23: =F4 -> 186340 | G23: =IF(F23>9000,9000*6%,F23*6%) -> 540 | H23: =IF(F23>99000,99000*6%,F23*6%-540) -> 5940 | I23: =SUM(G23:H23) -> 6480 | J23: =5%*F23 -> 9317 | K23: =10%*D23 -> 18634 | L23: =SUM(G23:K23) -> 40911 | M23: 30000 | N23: =IF(L23>M23,L23-M23,0) -> 10911
B24: 3 | C24: EMP040 | D24: =D5 -> 290950 | E24: =E5 -> 0 | F24: =F5 -> 290950 | G24: =IF(F24>9000,9000*6%,F24*6%) -> 540 | H24: =IF(F24>99000,99000*6%,F24*6%-540) -> 5940 | I24: =SUM(G24:H24) -> 6480 | J24: =5%*F24 -> 14547.5 | K24: =10%*D24 -> 29095 | L24: =SUM(G24:K24) -> 56602.5 | M24: 30000 | N24: =IF(L24>M24,L24-M24,0) -> 26602.5
B25: 4 | C25: EMP0089 | D25: =D6 -> 64790 | E25: =E6 -> 0 | F25: =F6 -> 64790 | G25: =IF(F25>9000,9000*6%,F25*6%) -> 540 | H25: =IF(F25>99000,99000*6%,F25*6%-540) -> 3347.4 | I25: =SUM(G25:H25) -> 3887.4 | J25: =5%*F25 -> 3239.5 | K25: =10%*D25 -> 6479 | L25: =SUM(G25:K25) -> 17493.3 | M25: 30000 | N25: =IF(L25>M25,L25-M25,0) -> 0
B26: 5 | C26: EMP0158 | D26: =D7 -> 333243.9 | E26: =E7 -> 48324 | F26: =F7 -> 381567.9 | G26: =IF(F26>9000,9000*6%,F26*6%) -> 540 | H26: =IF(F26>99000,99000*6%,F26*6%-540) -> 5940 | I26: =SUM(G26:H26) -> 6480 | J26: =5%*F26 -> 19078.395 | K26: =10%*D26 -> 33324.39 | L26: =SUM(G26:K26) -> 65362.785 | M26: 30000 | N26: =IF(L26>M26,L26-M26,0) -> 35362.785
B27: 6 | C27: EMP02024 | D27: =D8 -> 220000 | E27: =E8 -> 0 | F27: =F8 -> 220000 | G27: =IF(F27>9000,9000*6%,F27*6%) -> 540 | H27: =IF(F27>99000,99000*6%,F27*6%-540) -> 5940 | I27: =SUM(G27:H27) -> 6480 | J27: =5%*F27 -> 11000 | K27: =10%*D27 -> 22000 | L27: =SUM(G27:K27) -> 45960 | M27: 30000 | N27: =IF(L27>M27,L27-M27,0) -> 15960
B28: 7 | C28: EMP0303 | D28: =D9 -> 426250 | E28: =E9 -> 256795 | F28: =F9 -> 683045 | G28: =IF(F28>9000,9000*6%,F28*6%) -> 540 | H28: =IF(F28>99000,99000*6%,F28*6%-540) -> 5940 | I28: =SUM(G28:H28) -> 6480 | J28: =5%*F28 -> 34152.25 | K28: =10%*D28 -> 42625 | L28: =SUM(G28:K28) -> 89737.25 | M28: 30000 | N28: =IF(L28>M28,L28-M28,0) -> 59737.25
B29: 8 | C29: EMP0495 | D29: =D10 -> 580000 | E29: =E10 -> 78000 | F29: =F10 -> 658000 | G29: =IF(F29>9000,9000*6%,F29*6%) -> 540 | H29: =IF(F29>99000,99000*6%,F29*6%-540) -> 5940 | I29: =SUM(G29:H29) -> 6480 | J29: =5%*F29 -> 32900 | K29: =10%*D29 -> 58000 | L29: =SUM(G29:K29) -> 103860 | M29: 30000 | N29: =IF(L29>M29,L29-M29,0) -> 73860
B30: 9 | C30: EMP0500 | D30: =D11 -> 255750 | E30: =E11 -> 40575 | F30: =F11 -> 296325 | G30: =IF(F30>9000,9000*6%,F30*6%) -> 540 | H30: =IF(F30>99000,99000*6%,F30*6%-540) -> 5940 | I30: =SUM(G30:H30) -> 6480 | J30: =5%*F30 -> 14816.25 | K30: =10%*D30 -> 25575 | L30: =SUM(G30:K30) -> 53351.25 | M30: 30000 | N30: =IF(L30>M30,L30-M30,0) -> 23351.25
B31: 10 | C31: EMP0525 | D31: =D12 -> 426250 | E31: =E12 -> 62625 | F31: =F12 -> 488875 | G31: =IF(F31>9000,9000*6%,F31*6%) -> 540 | H31: =IF(F31>99000,99000*6%,F31*6%-540) -> 5940 | I31: =SUM(G31:H31) -> 6480 | J31: =5%*F31 -> 24443.75 | K31: =10%*D31 -> 42625 | L31: =SUM(G31:K31) -> 80028.75 | M31: 30000 | N31: =IF(L31>M31,L31-M31,0) -> 50028.75
B32: 11 | C32: EMP0547 | D32: =D13 -> 350000 | E32: =E13 -> 50000 | F32: =F13 -> 400000 | G32: =IF(F32>9000,9000*6%,F32*6%) -> 540 | H32: =IF(F32>99000,99000*6%,F32*6%-540) -> 5940 | I32: =SUM(G32:H32) -> 6480 | J32: =5%*F32 -> 20000 | K32: =10%*D32 -> 35000 | L32: =SUM(G32:K32) -> 67960 | M32: 30000 | N32: =IF(L32>M32,L32-M32,0) -> 37960
B33: 12 | C33: EMP1829 | D33: =D14 -> 333243.9 | E33: =E14 -> 172864 | F33: =F14 -> 506107.9 | G33: =IF(F33>9000,9000*6%,F33*6%) -> 540 | H33: =IF(F33>99000,99000*6%,F33*6%-540) -> 5940 | I33: =SUM(G33:H33) -> 6480 | J33: =5%*F33 -> 25305.395 | K33: =10%*D33 -> 33324.39 | L33: =SUM(G33:K33) -> 71589.785 | M33: 30000 | N33: =IF(L33>M33,L33-M33,0) -> 41589.785
B34: 13 | C34: EMP1836 | D34: =D15 -> 727500 | E34: =E15 -> 122775 | F34: =F15 -> 850275 | G34: =IF(F34>9000,9000*6%,F34*6%) -> 540 | H34: =IF(F34>99000,99000*6%,F34*6%-540) -> 5940 | I34: =SUM(G34:H34) -> 6480 | J34: =5%*F34 -> 42513.75 | K34: =10%*D34 -> 72750 | L34: =SUM(G34:K34) -> 128223.75 | M34: 30000 | N34: =IF(L34>M34,L34-M34,0) -> 98223.75
... B36: 15 | C36: EMP0673 | D36: =D17 -> 693564 | E36: =E17 -> 89356 | F36: =F17 -> 782920 | G36: =IF(F36>9000,9000*6%,F36*6%) -> 540 | H36: =IF(F36>99000,99000*6%,F36*6%-540) -> 5940 | I36: =SUM(G36:H36) -> 6480 | J36: =5%*F36 -> 39146 | K36: =10%*D36 -> 69356.4 | L36: =SUM(G36:K36) -> 121462.4 | M36: 30000 | N36: =IF(L36>M36,L36-M36,0) -> 91462.4
D37: =SUM(D22:D36) -> 5051551.8 | E37: =SUM(E22:E36) -> 921314 | F37: =SUM(F22:F36) -> 5972865.8 | G37: =SUM(G22:G36) -> 8100 | H37: =SUM(H22:H36) -> 82337.4 | I37: =SUM(I22:I36) -> 90437.4 | J37: =SUM(J22:J36) -> 298643.29 | K37: =SUM(K22:K36) -> 505155.18 | ... N37: =SUM(N22:N36) -> 566784.97
B39: TABLE C (DIFFERENCES BETWEEN A AND B) (Differences between Actual calculated and what ought to be)
B40: No. | C40: EMP. NO. | D40: Basic Pay | E40: Allowances | F40: Gross Pay | G40: NSSF Tier 1 Employee | H40: NSSF Tier 2 Employee | I40: NSSF (Employer) | J40: Pension (Employee)-5% of gross | K40: Pension (Employer)-10% of basic | L40: Total | M40: Limit | N40: Excess
B41: 1 | C41: EMP3866 | D41: =D3-D22 -> 0 | E41: =E3-E22 -> 0 | F41: =F3-F22 -> 0 | G41: =G3-G22 -> 0 | H41: =H3-H22 -> 0 | I41: =I3-I22 -> 0 | J41: =J3-J22 -> 0 | K41: =K3-K22 -> 0 | ... N41: =N3-N22 -> 0
B42: 2 | C42: EMP004 | D42: =D4-D23 -> 0 | E42: 0 | F42: =D42+E42 -> 0 | G42: =G4-G23 -> 0 | H42: =H4-H23 -> 0 | I42: =I4-I23 -> 0 | J42: =J4-J23 -> 0 | K42: =K4-K23 -> 0 | L42: =L4-L23 -> 0 | M42: =M4-M23 -> 0 | N42: =N4-N23 -> 0
...

Sheet Sheet3
A1: No. | B1: Employee No. | C1: Variance in Employee Pension / Excess Pension (KES) | D1: Basis of variance
A2: 1 | B2: EMP0158 | C2: 2416.2 | D2: 5% applied to basic instead of gross
A3: 2 | B3: EMP0303 | C3: 12839.75 | D3: 5% applied to basic instead of gross
A4: 3 | B4: EMP0495 | C4: 3900 | D4: 5% applied to basic instead of gross
A5: 4 | B5: EMP0500 | C5: 2028.75 | D5: 5% applied to basic instead of gross
A6: 5 | B6: EMP0525 | C6: 3131.25 | D6: 5% applied to basic instead of gross
A7: 6 | B7: EMP0547 | C7: 2500 | D7: 5% applied to basic instead of gross
A8: 7 | B8: EMP1829 | C8: 8643.2 | D8: 5% applied to basic instead of gross
A9: 8 | B9: EMP1836 | C9: 6138.75 | D9: 5% applied to basic instead of gross
A10: 9 | B10: EMP0673 | C10: 4467.8 | D10: 5% applied to basic instead of gross
B11: Total | C11: 46065.7

Sheet Remittance 
A2: 1 | B2: PAYE inclusive of Tax on excess pension
